<mujoco model="DOG">
  <compiler angle="radian" meshdir="./meshes/"/>
    <!-- <default>
        <geom solref = "0.005 1" condim = "3" friction = "1 1" />
        <equality solref = "0.005 1" />
    </default> -->
  <default>
      <geom contype="1" conaffinity="1" friction="2.0 1.5 0.1" rgba="0.5 0.6 0.7 1" margin="0.001" group="0"/>  
      <light castshadow="true" diffuse="1 1 1" specular="0.5 0.5 0.5"/>
      <motor ctrlrange="-200 200" ctrllimited="true"/>
      <camera fovy="60"/>
      <joint damping="0.01" armature="0.01" frictionloss="0.2" />
  </default>
  <asset>
    <mesh name="BASE_LINK" file="BASE_LINK.STL"/>
    <mesh name="FL_ABAD_LINK" file="FL_ABAD_LINK.STL"/>
    <mesh name="FL_HIP_LINK" file="FL_HIP_LINK.STL"/>
    <mesh name="FL_KNEE_LINK" file="FL_KNEE_LINK.STL"/>
    <mesh name="FL_FOOT_LINK" file="FL_FOOT_LINK.STL"/>
    <mesh name="FR_ABAD_LINK" file="FR_ABAD_LINK.STL"/>
    <mesh name="FR_HIP_LINK" file="FR_HIP_LINK.STL"/>
    <mesh name="FR_KNEE_LINK" file="FR_KNEE_LINK.STL"/>
    <mesh name="FR_FOOT_LINK" file="FR_FOOT_LINK.STL"/>
    <mesh name="RR_ABAD_LINK" file="RR_ABAD_LINK.STL"/>
    <mesh name="RR_HIP_LINK" file="RR_HIP_LINK.STL"/>
    <mesh name="RR_KNEE_LINK" file="RR_KNEE_LINK.STL"/>
    <mesh name="RR_FOOT_LINK" file="RR_FOOT_LINK.STL"/>
    <mesh name="RL_ABAD_LINK" file="RL_ABAD_LINK.STL"/>
    <mesh name="RL_HIP_LINK" file="RL_HIP_LINK.STL"/>
    <mesh name="RL_KNEE_LINK" file="RL_KNEE_LINK.STL"/>
    <mesh name="RL_FOOT_LINK" file="RL_FOOT_LINK.STL"/>
  </asset>
  <asset>
    <texture type="skybox" builtin="gradient" rgb1="1.0 1.0 1.0" rgb2="1.0 1.0 1.0" width="512" height="512"/>
    <texture name="plane" type="2d" builtin="checker" rgb1="0.8 0.8 0.8" rgb2="0.4 0.4 0.4" width="512" height="512"/>
    <material name="plane" reflectance="0.5" texture="plane" texrepeat="10 10" texuniform="true"/>
  </asset>

  <worldbody>
    <camera name="track" mode="trackcom" pos="0 -1.3 1.6" xyaxes="1 0 0 0 0.707 0.707" fovy="45"/>
    <geom name='floor' type='plane' conaffinity='1' condim='3' contype='1' material='plane' pos='0 0 0' size='0 0 1'/>
    <body name="base" pos="0 0 0.45">
      <inertial pos="0.0054244583 -0.00036330247 0.0060908623"  mass="6.268375" diaginertia="0.027359128 0.084984679 0.099223551" />
      <joint type="free" />
      <site name = "imu" size = "0.01" pos = "0 0 0" />
      <geom type="mesh" contype="0" conaffinity="0" group="1" rgba="0.75294 0.75294 0.75294 1" mesh="BASE_LINK"/>
      <body name="FL_hip" pos="0.17449 0.062 0">
        <inertial pos="-0.0270745 -0.0154588 9.41679e-06" quat="0.600186 0.60017 0.373963 0.373798" mass="0.454098" diaginertia="0.000562658 0.000541021 0.00017585"/>
        <joint name="FL_hip_joint" pos="0 0 0" axis="1 0 0" range="-0.4887 0.4887" actuatorfrcrange="-28 28" />
        <geom type="mesh" contype="0" conaffinity="0" group="1" density="0" rgba="0.75294 0.75294 0.75294 1" mesh="FL_ABAD_LINK"/>
        <geom size="0.038 0.045" pos="0 0.054 0" quat="0.707107 0.707107 0 0" type="cylinder" rgba="0.75294 0.75294 0.75294 1"/>
        <body name="FL_thigh" pos="0 0.097412 0">
          <inertial pos="-0.00334388 -0.042909 -0.0216077" quat="0.961876 0.267908 0.0543528 0.00804932" mass="1.50165" diaginertia="0.00700226 0.00563861 0.0023263"/>
          <joint name="FL_thigh_joint" pos="0 0 0" axis="0 1 0" range="-1.1519 2.967" actuatorfrcrange="-28 28"/>
          <geom type="mesh" contype="0" conaffinity="0" group="1" density="0" rgba="0.75294 0.75294 0.75294 1" mesh="FL_HIP_LINK"/>
          <geom size="0.055 0.01225 0.017" pos="0 0 -0.1065" quat="0.707107 0 0.707107 0" type="box" rgba="0.75294 0.75294 0.75294 1"/>
          <body name="FL_calf" pos="0 0 -0.2">
            <inertial pos="0.00484121 0 -0.122269" quat="0.707051 0.00673184 0.00672643 0.707099" mass="0.270529" diaginertia="0.00247753 0.00243753 7.93221e-05"/>
            <joint name="FL_calf_joint" pos="0 0 0" axis="0 1 0" range="-2.723 -0.602" actuatorfrcrange="-28 28"/>
            <geom type="mesh" contype="0" conaffinity="0" group="1" density="0" rgba="0.49804 0.49804 0.49804 1" mesh="FL_KNEE_LINK"/>
            <geom size="0.02 0.01 0.02" pos="0.015 0 -0.17" quat="0.968912 0 0.247404 0" type="box" rgba="0.49804 0.49804 0.49804 1"/>
            <geom size="0.016 0.01 0.09" pos="0.0085 0 -0.06" quat="0.997189 0 -0.0749297 0" type="box" rgba="0.49804 0.49804 0.49804 1"/>

            <body name="FL_foot" pos="0 0 0">
                <inertial pos="0 0 0" mass="0.06" diaginertia="9.6e-06 9.6e-06 9.6e-06" />
                <!-- <geom name="FL_foot_geom" size="0.02" type="sphere" solref="0.01 20" solimp="0.6 0.95 0.001" contype="1" conaffinity="1" rgba="0 0 0 1" /> -->
                <geom pos="0 0 -0.21366" quat="1 0 0 0" type="mesh" contype="0" conaffinity="0" group="1" density="0" rgba="0.75294 0.75294 0.75294 1" mesh="FL_FOOT_LINK"/>
                <geom size="0.026" pos="0 0 -0.21366" rgba="0.75294 0.75294 0.75294 1"/>
            </body>
          </body>
        </body>
      </body>
      <body name="FR_hip" pos="0.17449 -0.062 0">
        <inertial pos="-0.0270745 0.0154588 -9.41679e-06" quat="0.373963 0.373798 0.600186 0.60017" mass="0.454098" diaginertia="0.000562658 0.000541021 0.00017585"/>
        <joint name="FR_hip_joint" pos="0 0 0" axis="1 0 0" range="-0.4887 0.4887" actuatorfrcrange="-28 28"/>
        <geom type="mesh" contype="0" conaffinity="0" group="1" density="0" rgba="0.75294 0.75294 0.75294 1" mesh="FR_ABAD_LINK"/>
        <geom size="0.038 0.045" pos="0 -0.054 0" quat="0.707107 0.707107 0 0" type="cylinder" rgba="0.75294 0.75294 0.75294 1"/>
        <body name="FR_thigh" pos="0 -0.097399 0">
          <inertial pos="-0.00342445 0.0427303 -0.0223257" quat="0.964115 -0.259871 0.0534872 -0.00934672" mass="1.50799" diaginertia="0.00720259 0.00582228 0.00234676"/>
          <joint name="FR_thigh_joint" pos="0 0 0" axis="0 1 0" range="-1.1519 2.967" actuatorfrcrange="-28 28"/>
          <geom type="mesh" contype="0" conaffinity="0" group="1" density="0" rgba="0.75294 0.75294 0.75294 1" mesh="FR_HIP_LINK"/>
          <geom size="0.055 0.01225 0.017" pos="0 0 -0.1065" quat="0.707107 0 0.707107 0" type="box" rgba="0.75294 0.75294 0.75294 1"/>
          <body name="FR_calf" pos="0 0 -0.2">
            <inertial pos="0.00484121 0 -0.122269" quat="0.707051 0.00673184 0.00672643 0.707099" mass="0.270529" diaginertia="0.00247753 0.00243753 7.93221e-05"/>
            <joint name="FR_calf_joint" pos="0 0 0" axis="0 1 0" range="-2.723 -0.602" actuatorfrcrange="-28 28"/>
            <geom type="mesh" contype="0" conaffinity="0" group="1" density="0" rgba="0.49804 0.49804 0.49804 1" mesh="FR_KNEE_LINK"/>
            <geom size="0.02 0.01 0.02" pos="0.015 0 -0.17" quat="0.968912 0 0.247404 0" type="box" rgba="0.49804 0.49804 0.49804 1"/>
            <geom size="0.016 0.01 0.09" pos="0.0085 0 -0.06" quat="0.997189 0 -0.0749297 0" type="box" rgba="0.49804 0.49804 0.49804 1"/>

            <body name="FR_foot" pos="0 0 0">
                <inertial pos="0 0 0" mass="0.06" diaginertia="9.6e-06 9.6e-06 9.6e-06" />
                <!-- <geom name="FR_foot_geom" size="0.02" type="sphere" solref="0.01 20" solimp="0.6 0.95 0.001" contype="1" conaffinity="1" rgba="0 0 0 1" /> -->
                <geom pos="0 0 -0.21366" quat="1 0 0 0" type="mesh" contype="0" conaffinity="0" group="1" density="0" rgba="0.75294 0.75294 0.75294 1" mesh="FR_FOOT_LINK"/>
                <geom size="0.026" pos="0 0 -0.21366" rgba="0.75294 0.75294 0.75294 1"/>
            </body>
          </body>
        </body>
      </body>
      <body name="RL_hip" pos="-0.17449 0.062 0">
        <inertial pos="0.0270745 -0.0154588 -9.41679e-06" quat="0.373798 0.373963 0.60017 0.600186" mass="0.454098" diaginertia="0.000562658 0.000541021 0.00017585"/>
        <joint name="RL_hip_joint" pos="0 0 0" axis="1 0 0" range="-0.4887 0.4887" actuatorfrcrange="-28 28"/>
        <geom type="mesh" contype="0" conaffinity="0" group="1" density="0" rgba="0.75294 0.75294 0.75294 1" mesh="RL_ABAD_LINK"/>
        <geom size="0.038 0.045" pos="0 0.054 0" quat="0.707107 0.707107 0 0" type="cylinder" rgba="0.75294 0.75294 0.75294 1"/>
        <body name="RL_thigh" pos="0 0.097412 0">
          <inertial pos="-0.00334388 -0.042909 -0.0216077" quat="0.961876 0.267908 0.0543528 0.00804932" mass="1.50165" diaginertia="0.00700226 0.00563861 0.0023263"/>
          <joint name="RL_thigh_joint" pos="0 0 0" axis="0 1 0" range="-1.1519 2.967" actuatorfrcrange="-28 28"/>
          <geom type="mesh" contype="0" conaffinity="0" group="1" density="0" rgba="0.75294 0.75294 0.75294 1" mesh="RL_HIP_LINK"/>
          <geom size="0.055 0.01225 0.017" pos="0 0 -0.1065" quat="0.707107 0 0.707107 0" type="box" rgba="0.75294 0.75294 0.75294 1"/>
          <body name="RL_calf" pos="0 0 -0.2">
            <inertial pos="0.00484121 0 -0.122269" quat="0.707051 0.00673184 0.00672643 0.707099" mass="0.270529" diaginertia="0.00247753 0.00243753 7.93221e-05"/>
            <joint name="RL_calf_joint" pos="0 0 0" axis="0 1 0" range="-2.723 -0.602" actuatorfrcrange="-28 28"/>
            <geom type="mesh" contype="0" conaffinity="0" group="1" density="0" rgba="0.49804 0.49804 0.49804 1" mesh="RL_KNEE_LINK"/>
            <geom size="0.02 0.01 0.02" pos="0.015 0 -0.17" quat="0.968912 0 0.247404 0" type="box" rgba="0.49804 0.49804 0.49804 1"/>
            <geom size="0.016 0.01 0.09" pos="0.0085 0 -0.06" quat="0.997189 0 -0.0749297 0" type="box" rgba="0.49804 0.49804 0.49804 1"/>

            <body name="RL_foot" pos="0 0 0">
                <inertial pos="0 0 0" mass="0.06" diaginertia="9.6e-06 9.6e-06 9.6e-06" />
                <!-- <geom name="RL_foot_geom" size="0.02" type="sphere" solref="0.01 20" solimp="0.6 0.95 0.001" contype="1" conaffinity="1" rgba="0 0 0 1" /> -->
                <geom pos="0 0 -0.21366" quat="1 0 0 0" type="mesh" contype="0" conaffinity="0" group="1" density="0" rgba="0.75294 0.75294 0.75294 1" mesh="RL_FOOT_LINK"/>
                <geom size="0.026" pos="0 0 -0.21366" rgba="0.75294 0.75294 0.75294 1"/>
            </body>
          </body>
        </body>
      </body>
      <body name="RR_hip" pos="-0.17449 -0.062 0">
        <inertial pos="0.0270745 0.0154588 9.41679e-06" quat="0.60017 0.600186 0.373798 0.373963" mass="0.454098" diaginertia="0.000562658 0.000541021 0.00017585"/>
        <joint name="RR_hip_joint" pos="0 0 0" axis="1 0 0" range="-0.4887 0.4887" actuatorfrcrange="-28 28"/>
        <geom type="mesh" contype="0" conaffinity="0" group="1" density="0" rgba="0.75294 0.75294 0.75294 1" mesh="RR_ABAD_LINK"/>
        <geom size="0.038 0.045" pos="0 -0.054 0" quat="0.707107 0.707107 0 0" type="cylinder" rgba="0.75294 0.75294 0.75294 1"/>
        <body name="RR_thigh" pos="0 -0.0974 0">
          <inertial pos="-0.00342445 0.0427303 -0.0223257" quat="0.964115 -0.259871 0.0534872 -0.00934672" mass="1.50799" diaginertia="0.00720259 0.00582228 0.00234676"/>
          <joint name="RR_thigh_joint" pos="0 0 0" axis="0 1 0" range="-1.1519 2.967" actuatorfrcrange="-28 28"/>
          <geom type="mesh" contype="0" conaffinity="0" group="1" density="0" rgba="0.75294 0.75294 0.75294 1" mesh="RR_HIP_LINK"/>
          <geom size="0.055 0.01225 0.017" pos="0 0 -0.1065" quat="0.707107 0 0.707107 0" type="box" rgba="0.75294 0.75294 0.75294 1"/>
          <body name="RR_calf" pos="0 0 -0.2">
            <inertial pos="0.00484121 0 -0.122269" quat="0.707051 0.00673184 0.00672643 0.707099" mass="0.270529" diaginertia="0.00247753 0.00243753 7.93221e-05"/>
            <joint name="RR_calf_joint" pos="0 0 0" axis="0 1 0" range="-2.723 -0.602" actuatorfrcrange="-28 28"/>
            <geom type="mesh" contype="0" conaffinity="0" group="1" density="0" rgba="0.49804 0.49804 0.49804 1" mesh="RR_KNEE_LINK"/>
            <geom size="0.02 0.01 0.02" pos="0.015 0 -0.17" quat="0.968912 0 0.247404 0" type="box" rgba="0.49804 0.49804 0.49804 1"/>
            <geom size="0.016 0.01 0.09" pos="0.0085 0 -0.06" quat="0.997189 0 -0.0749297 0" type="box" rgba="0.49804 0.49804 0.49804 1"/>

            <body name="RR_foot" pos="0 0 0">
                <inertial pos="0 0 0" mass="0.06" diaginertia="9.6e-06 9.6e-06 9.6e-06" />
                <!-- <geom name="RR_foot_geom" size="0.02" type="sphere" solref="0.01 20" solimp="0.6 0.95 0.001" contype="1" conaffinity="1" rgba="0 0 0 1" /> -->
                <geom pos="0 0 -0.21366" quat="1 0 0 0" type="mesh" contype="0" conaffinity="0" group="1" density="0" rgba="0.75294 0.75294 0.75294 1" mesh="RR_FOOT_LINK"/>
                <geom size="0.026" pos="0 0 -0.21366" rgba="0.75294 0.75294 0.75294 1"/>
            </body>
          </body>
        </body>
      </body>
    </body>
  </worldbody>

  <actuator>
    <motor name="FL_hip"   joint="FL_hip_joint" ctrlrange = '-120 120'/>
    <motor name="FL_thigh" joint="FL_thigh_joint" ctrlrange = '-120 120'/>
    <motor name="FL_calf"  joint="FL_calf_joint"ctrlrange = '-120 120'/>
    <motor name="FR_hip"   joint="FR_hip_joint" ctrlrange = '-120 120'/>
    <motor name="FR_thigh" joint="FR_thigh_joint" ctrlrange = '-120 120'/>
    <motor name="FR_calf"  joint="FR_calf_joint" ctrlrange = '-120 120'/>
    <motor name="RL_hip"   joint="RL_hip_joint" ctrlrange = '-120 120'/>
    <motor name="RL_thigh" joint="RL_thigh_joint" ctrlrange = '-120 120'/>
    <motor name="RL_calf"  joint="RL_calf_joint" ctrlrange = '-120 120'/>
    <motor name="RR_hip"   joint="RR_hip_joint" ctrlrange = '-120 120'/>
    <motor name="RR_thigh" joint="RR_thigh_joint" ctrlrange = '-120 120'/>
    <motor name="RR_calf"  joint="RR_calf_joint" ctrlrange = '-120 120'/>
  </actuator>

  <sensor>
    <jointpos name="FL_hip_pos"     joint="FL_hip_joint"/>
    <jointpos name="FL_thigh_pos"   joint="FL_thigh_joint"/>
    <jointpos name="FL_calf_pos"    joint="FL_calf_joint"/>
    <jointpos name="FR_hip_pos"     joint="FR_hip_joint"/>
    <jointpos name="FR_thigh_pos"   joint="FR_thigh_joint"/>
    <jointpos name="FR_calf_pos"    joint="FR_calf_joint"/>

    <jointpos name="RL_hip_pos"     joint="RL_hip_joint"/>
    <jointpos name="RL_thigh_pos"   joint="RL_thigh_joint"/>
    <jointpos name="RL_calf_pos"    joint="RL_calf_joint"/>
    <jointpos name="RR_hip_pos"     joint="RR_hip_joint"/>
    <jointpos name="RR_thigh_pos"   joint="RR_thigh_joint"/>
    <jointpos name="RR_calf_pos"    joint="RR_calf_joint" />
   

    <jointvel name="FL_hip_vel"     joint="FL_hip_joint"/>
    <jointvel name="FL_thigh_vel"   joint="FL_thigh_joint"/>
    <jointvel name="FL_calf_vel"    joint="FL_calf_joint"/>
    <jointvel name="FR_hip_vel"     joint="FR_hip_joint"/>
    <jointvel name="FR_thigh_vel"   joint="FR_thigh_joint"/>
    <jointvel name="FR_calf_vel"    joint="FR_calf_joint"/>

    <jointvel name="RL_hip_vel"     joint="RL_hip_joint"/>
    <jointvel name="RL_thigh_vel"   joint="RL_thigh_joint"/>
    <jointvel name="RL_calf_vel"    joint="RL_calf_joint"/>
    <jointvel name="RR_hip_vel"     joint="RR_hip_joint"/>
    <jointvel name="RR_thigh_vel"   joint="RR_thigh_joint"/>
    <jointvel name="RR_calf_vel"    joint="RR_calf_joint" />
   

    <framequat name="body-orientation" objtype="site" objname="imu"/>
    <gyro name="body-angular-velocity" site="imu"/>
    <framepos name="body-linear-pos" objtype="site" objname="imu"/>
    <velocimeter name="body-linear-vel" site="imu"/>
    <accelerometer name="body-linear-acceleration" site="imu"/>
  </sensor>
</mujoco>
